2020-07-14 14:27:43,408 ERROR: Exception on /api/users [GET] [in /Users/connorreitz/Documents/Programming/flask_webapp/venv/lib/python3.8/site-packages/flask/app.py:1890]
Traceback (most recent call last):
  File "/Users/connorreitz/Documents/Programming/flask_webapp/venv/lib/python3.8/site-packages/flask/app.py", line 2446, in wsgi_app
    response = self.full_dispatch_request()
  File "/Users/connorreitz/Documents/Programming/flask_webapp/venv/lib/python3.8/site-packages/flask/app.py", line 1951, in full_dispatch_request
    rv = self.handle_user_exception(e)
  File "/Users/connorreitz/Documents/Programming/flask_webapp/venv/lib/python3.8/site-packages/flask/app.py", line 1820, in handle_user_exception
    reraise(exc_type, exc_value, tb)
  File "/Users/connorreitz/Documents/Programming/flask_webapp/venv/lib/python3.8/site-packages/flask/_compat.py", line 39, in reraise
    raise value
  File "/Users/connorreitz/Documents/Programming/flask_webapp/venv/lib/python3.8/site-packages/flask/app.py", line 1949, in full_dispatch_request
    rv = self.dispatch_request()
  File "/Users/connorreitz/Documents/Programming/flask_webapp/venv/lib/python3.8/site-packages/flask/app.py", line 1935, in dispatch_request
    return self.view_functions[rule.endpoint](**req.view_args)
  File "/Users/connorreitz/Documents/Programming/flask_webapp/app/api/users.py", line 13, in get_users
    data = User.to_collection_dict(User.query, page, per_page, 'api.get_users')
  File "/Users/connorreitz/Documents/Programming/flask_webapp/app/models.py", line 22, in to_collection_dict
    'items': [item.to_dict() for item in resources.items],
  File "/Users/connorreitz/Documents/Programming/flask_webapp/app/models.py", line 22, in <listcomp>
    'items': [item.to_dict() for item in resources.items],
  File "/Users/connorreitz/Documents/Programming/flask_webapp/app/models.py", line 108, in to_dict
    'last_seen': self.last_seen.isoformat() + 'Z',
AttributeError: 'NoneType' object has no attribute 'isoformat'
2020-07-14 14:31:16,946 INFO: Reitz Recipes startup [in /Users/connorreitz/Documents/Programming/flask_webapp/app/__init__.py:77]
2020-07-14 14:31:20,832 INFO: Reitz Recipes startup [in /Users/connorreitz/Documents/Programming/flask_webapp/app/__init__.py:77]
2020-07-14 14:33:14,791 ERROR: Exception on /follow/jon [POST] [in /Users/connorreitz/Documents/Programming/flask_webapp/venv/lib/python3.8/site-packages/flask/app.py:1890]
Traceback (most recent call last):
  File "/Users/connorreitz/Documents/Programming/flask_webapp/venv/lib/python3.8/site-packages/flask/app.py", line 2446, in wsgi_app
    response = self.full_dispatch_request()
  File "/Users/connorreitz/Documents/Programming/flask_webapp/venv/lib/python3.8/site-packages/flask/app.py", line 1951, in full_dispatch_request
    rv = self.handle_user_exception(e)
  File "/Users/connorreitz/Documents/Programming/flask_webapp/venv/lib/python3.8/site-packages/flask/app.py", line 1820, in handle_user_exception
    reraise(exc_type, exc_value, tb)
  File "/Users/connorreitz/Documents/Programming/flask_webapp/venv/lib/python3.8/site-packages/flask/_compat.py", line 39, in reraise
    raise value
  File "/Users/connorreitz/Documents/Programming/flask_webapp/venv/lib/python3.8/site-packages/flask/app.py", line 1949, in full_dispatch_request
    rv = self.dispatch_request()
  File "/Users/connorreitz/Documents/Programming/flask_webapp/venv/lib/python3.8/site-packages/flask/app.py", line 1935, in dispatch_request
    return self.view_functions[rule.endpoint](**req.view_args)
  File "/Users/connorreitz/Documents/Programming/flask_webapp/venv/lib/python3.8/site-packages/flask_login/utils.py", line 272, in decorated_view
    return func(*args, **kwargs)
  File "/Users/connorreitz/Documents/Programming/flask_webapp/app/main/routes.py", line 105, in follow
    return redirect(url_for('user', username=username))
  File "/Users/connorreitz/Documents/Programming/flask_webapp/venv/lib/python3.8/site-packages/flask/helpers.py", line 370, in url_for
    return appctx.app.handle_url_build_error(error, endpoint, values)
  File "/Users/connorreitz/Documents/Programming/flask_webapp/venv/lib/python3.8/site-packages/flask/app.py", line 2215, in handle_url_build_error
    reraise(exc_type, exc_value, tb)
  File "/Users/connorreitz/Documents/Programming/flask_webapp/venv/lib/python3.8/site-packages/flask/_compat.py", line 39, in reraise
    raise value
  File "/Users/connorreitz/Documents/Programming/flask_webapp/venv/lib/python3.8/site-packages/flask/helpers.py", line 357, in url_for
    rv = url_adapter.build(
  File "/Users/connorreitz/Documents/Programming/flask_webapp/venv/lib/python3.8/site-packages/werkzeug/routing.py", line 2179, in build
    raise BuildError(endpoint, values, method, self)
werkzeug.routing.BuildError: Could not build url for endpoint 'user' with values ['username']. Did you mean 'main.user' instead?
2020-07-14 14:35:01,715 INFO: Reitz Recipes startup [in /Users/connorreitz/Documents/Programming/flask_webapp/app/__init__.py:77]
2020-07-14 14:50:36,759 INFO: Reitz Recipes startup [in /Users/connorreitz/Documents/Programming/flask_webapp/app/__init__.py:77]
2020-07-14 14:50:48,391 INFO: Reitz Recipes startup [in /Users/connorreitz/Documents/Programming/flask_webapp/app/__init__.py:77]
2020-07-14 15:06:36,801 INFO: Reitz Recipes startup [in /Users/connorreitz/Documents/Programming/flask_webapp/app/__init__.py:77]
