2020-07-05 18:10:07,769 ERROR: Exception on /search [GET] [in /Users/connorreitz/Documents/Programming/flask_webapp/venv/lib/python3.8/site-packages/flask/app.py:1890]
Traceback (most recent call last):
  File "/Users/connorreitz/Documents/Programming/flask_webapp/venv/lib/python3.8/site-packages/flask/app.py", line 2446, in wsgi_app
    response = self.full_dispatch_request()
  File "/Users/connorreitz/Documents/Programming/flask_webapp/venv/lib/python3.8/site-packages/flask/app.py", line 1951, in full_dispatch_request
    rv = self.handle_user_exception(e)
  File "/Users/connorreitz/Documents/Programming/flask_webapp/venv/lib/python3.8/site-packages/flask/app.py", line 1820, in handle_user_exception
    reraise(exc_type, exc_value, tb)
  File "/Users/connorreitz/Documents/Programming/flask_webapp/venv/lib/python3.8/site-packages/flask/_compat.py", line 39, in reraise
    raise value
  File "/Users/connorreitz/Documents/Programming/flask_webapp/venv/lib/python3.8/site-packages/flask/app.py", line 1949, in full_dispatch_request
    rv = self.dispatch_request()
  File "/Users/connorreitz/Documents/Programming/flask_webapp/venv/lib/python3.8/site-packages/flask/app.py", line 1935, in dispatch_request
    return self.view_functions[rule.endpoint](**req.view_args)
  File "/Users/connorreitz/Documents/Programming/flask_webapp/venv/lib/python3.8/site-packages/flask_login/utils.py", line 272, in decorated_view
    return func(*args, **kwargs)
  File "/Users/connorreitz/Documents/Programming/flask_webapp/app/main/routes.py", line 135, in search
    posts, total = Post.search(g.search_form.q.data, page,
  File "/Users/connorreitz/Documents/Programming/flask_webapp/app/models.py", line 82, in search
    ids, total = query_index(cls.__tablename__, expression, page, per_page)
  File "/Users/connorreitz/Documents/Programming/flask_webapp/app/search.py", line 21, in query_index
    search = current_app.elasticsearch.search(
  File "/Users/connorreitz/Documents/Programming/flask_webapp/venv/lib/python3.8/site-packages/elasticsearch/client/utils.py", line 139, in _wrapped
    return func(*args, params=params, headers=headers, **kwargs)
  File "/Users/connorreitz/Documents/Programming/flask_webapp/venv/lib/python3.8/site-packages/elasticsearch/client/__init__.py", line 1479, in search
    return self.transport.perform_request(
  File "/Users/connorreitz/Documents/Programming/flask_webapp/venv/lib/python3.8/site-packages/elasticsearch/transport.py", line 345, in perform_request
    status, headers_response, data = connection.perform_request(
  File "/Users/connorreitz/Documents/Programming/flask_webapp/venv/lib/python3.8/site-packages/elasticsearch/connection/http_urllib3.py", line 256, in perform_request
    self._raise_error(response.status, raw_data)
  File "/Users/connorreitz/Documents/Programming/flask_webapp/venv/lib/python3.8/site-packages/elasticsearch/connection/base.py", line 287, in _raise_error
    raise HTTP_EXCEPTIONS.get(status_code, TransportError)(
elasticsearch.exceptions.NotFoundError: NotFoundError(404, 'index_not_found_exception', 'no such index [post]', post, index_or_alias)
2020-07-05 18:12:49,862 INFO: Reitz Recipes startup [in /Users/connorreitz/Documents/Programming/flask_webapp/app/__init__.py:74]
2020-07-05 18:14:04,382 INFO: Reitz Recipes startup [in /Users/connorreitz/Documents/Programming/flask_webapp/app/__init__.py:74]
2020-07-05 18:14:10,036 ERROR: Exception on /search [GET] [in /Users/connorreitz/Documents/Programming/flask_webapp/venv/lib/python3.8/site-packages/flask/app.py:1890]
Traceback (most recent call last):
  File "/Users/connorreitz/Documents/Programming/flask_webapp/venv/lib/python3.8/site-packages/flask/app.py", line 2446, in wsgi_app
    response = self.full_dispatch_request()
  File "/Users/connorreitz/Documents/Programming/flask_webapp/venv/lib/python3.8/site-packages/flask/app.py", line 1951, in full_dispatch_request
    rv = self.handle_user_exception(e)
  File "/Users/connorreitz/Documents/Programming/flask_webapp/venv/lib/python3.8/site-packages/flask/app.py", line 1820, in handle_user_exception
    reraise(exc_type, exc_value, tb)
  File "/Users/connorreitz/Documents/Programming/flask_webapp/venv/lib/python3.8/site-packages/flask/_compat.py", line 39, in reraise
    raise value
  File "/Users/connorreitz/Documents/Programming/flask_webapp/venv/lib/python3.8/site-packages/flask/app.py", line 1949, in full_dispatch_request
    rv = self.dispatch_request()
  File "/Users/connorreitz/Documents/Programming/flask_webapp/venv/lib/python3.8/site-packages/flask/app.py", line 1935, in dispatch_request
    return self.view_functions[rule.endpoint](**req.view_args)
  File "/Users/connorreitz/Documents/Programming/flask_webapp/venv/lib/python3.8/site-packages/flask_login/utils.py", line 272, in decorated_view
    return func(*args, **kwargs)
  File "/Users/connorreitz/Documents/Programming/flask_webapp/app/main/routes.py", line 135, in search
    posts, total = Post.search(g.search_form.q.data, page,
  File "/Users/connorreitz/Documents/Programming/flask_webapp/app/models.py", line 82, in search
    ids, total = query_index(cls.__tablename__, expression, page, per_page)
  File "/Users/connorreitz/Documents/Programming/flask_webapp/app/search.py", line 21, in query_index
    search = current_app.elasticsearch.search(
  File "/Users/connorreitz/Documents/Programming/flask_webapp/venv/lib/python3.8/site-packages/elasticsearch/client/utils.py", line 139, in _wrapped
    return func(*args, params=params, headers=headers, **kwargs)
  File "/Users/connorreitz/Documents/Programming/flask_webapp/venv/lib/python3.8/site-packages/elasticsearch/client/__init__.py", line 1479, in search
    return self.transport.perform_request(
  File "/Users/connorreitz/Documents/Programming/flask_webapp/venv/lib/python3.8/site-packages/elasticsearch/transport.py", line 345, in perform_request
    status, headers_response, data = connection.perform_request(
  File "/Users/connorreitz/Documents/Programming/flask_webapp/venv/lib/python3.8/site-packages/elasticsearch/connection/http_urllib3.py", line 256, in perform_request
    self._raise_error(response.status, raw_data)
  File "/Users/connorreitz/Documents/Programming/flask_webapp/venv/lib/python3.8/site-packages/elasticsearch/connection/base.py", line 287, in _raise_error
    raise HTTP_EXCEPTIONS.get(status_code, TransportError)(
elasticsearch.exceptions.NotFoundError: NotFoundError(404, 'index_not_found_exception', 'no such index [post]', post, index_or_alias)
2020-07-05 18:18:56,689 INFO: Reitz Recipes startup [in /Users/connorreitz/Documents/Programming/flask_webapp/app/__init__.py:74]
2020-07-05 18:19:04,754 ERROR: Exception on /search [GET] [in /Users/connorreitz/Documents/Programming/flask_webapp/venv/lib/python3.8/site-packages/flask/app.py:1890]
Traceback (most recent call last):
  File "/Users/connorreitz/Documents/Programming/flask_webapp/venv/lib/python3.8/site-packages/flask/app.py", line 2446, in wsgi_app
    response = self.full_dispatch_request()
  File "/Users/connorreitz/Documents/Programming/flask_webapp/venv/lib/python3.8/site-packages/flask/app.py", line 1951, in full_dispatch_request
    rv = self.handle_user_exception(e)
  File "/Users/connorreitz/Documents/Programming/flask_webapp/venv/lib/python3.8/site-packages/flask/app.py", line 1820, in handle_user_exception
    reraise(exc_type, exc_value, tb)
  File "/Users/connorreitz/Documents/Programming/flask_webapp/venv/lib/python3.8/site-packages/flask/_compat.py", line 39, in reraise
    raise value
  File "/Users/connorreitz/Documents/Programming/flask_webapp/venv/lib/python3.8/site-packages/flask/app.py", line 1949, in full_dispatch_request
    rv = self.dispatch_request()
  File "/Users/connorreitz/Documents/Programming/flask_webapp/venv/lib/python3.8/site-packages/flask/app.py", line 1935, in dispatch_request
    return self.view_functions[rule.endpoint](**req.view_args)
  File "/Users/connorreitz/Documents/Programming/flask_webapp/venv/lib/python3.8/site-packages/flask_login/utils.py", line 272, in decorated_view
    return func(*args, **kwargs)
  File "/Users/connorreitz/Documents/Programming/flask_webapp/app/main/routes.py", line 135, in search
    posts, total = Post.search(g.search_form.q.data, page,
  File "/Users/connorreitz/Documents/Programming/flask_webapp/app/models.py", line 82, in search
    ids, total = query_index(cls.__tablename__, expression, page, per_page)
  File "/Users/connorreitz/Documents/Programming/flask_webapp/app/search.py", line 21, in query_index
    search = current_app.elasticsearch.search(
  File "/Users/connorreitz/Documents/Programming/flask_webapp/venv/lib/python3.8/site-packages/elasticsearch/client/utils.py", line 139, in _wrapped
    return func(*args, params=params, headers=headers, **kwargs)
  File "/Users/connorreitz/Documents/Programming/flask_webapp/venv/lib/python3.8/site-packages/elasticsearch/client/__init__.py", line 1479, in search
    return self.transport.perform_request(
  File "/Users/connorreitz/Documents/Programming/flask_webapp/venv/lib/python3.8/site-packages/elasticsearch/transport.py", line 345, in perform_request
    status, headers_response, data = connection.perform_request(
  File "/Users/connorreitz/Documents/Programming/flask_webapp/venv/lib/python3.8/site-packages/elasticsearch/connection/http_urllib3.py", line 256, in perform_request
    self._raise_error(response.status, raw_data)
  File "/Users/connorreitz/Documents/Programming/flask_webapp/venv/lib/python3.8/site-packages/elasticsearch/connection/base.py", line 287, in _raise_error
    raise HTTP_EXCEPTIONS.get(status_code, TransportError)(
elasticsearch.exceptions.NotFoundError: NotFoundError(404, 'index_not_found_exception', 'no such index [post]', post, index_or_alias)
2020-07-05 18:39:19,869 INFO: Reitz Recipes startup [in /Users/connorreitz/Documents/Programming/flask_webapp/app/__init__.py:74]
2020-07-05 18:40:21,589 INFO: Reitz Recipes startup [in /Users/connorreitz/Documents/Programming/flask_webapp/app/__init__.py:74]
