2020-06-30 08:48:30,477 ERROR: Exception on /user/con [GET] [in /Users/connorreitz/Documents/Programming/flask_webapp/venv/lib/python3.8/site-packages/flask/app.py:1890]
Traceback (most recent call last):
  File "/Users/connorreitz/Documents/Programming/flask_webapp/venv/lib/python3.8/site-packages/flask/app.py", line 2446, in wsgi_app
    response = self.full_dispatch_request()
  File "/Users/connorreitz/Documents/Programming/flask_webapp/venv/lib/python3.8/site-packages/flask/app.py", line 1951, in full_dispatch_request
    rv = self.handle_user_exception(e)
  File "/Users/connorreitz/Documents/Programming/flask_webapp/venv/lib/python3.8/site-packages/flask/app.py", line 1820, in handle_user_exception
    reraise(exc_type, exc_value, tb)
  File "/Users/connorreitz/Documents/Programming/flask_webapp/venv/lib/python3.8/site-packages/flask/_compat.py", line 39, in reraise
    raise value
  File "/Users/connorreitz/Documents/Programming/flask_webapp/venv/lib/python3.8/site-packages/flask/app.py", line 1949, in full_dispatch_request
    rv = self.dispatch_request()
  File "/Users/connorreitz/Documents/Programming/flask_webapp/venv/lib/python3.8/site-packages/flask/app.py", line 1935, in dispatch_request
    return self.view_functions[rule.endpoint](**req.view_args)
  File "/Users/connorreitz/Documents/Programming/flask_webapp/venv/lib/python3.8/site-packages/flask_login/utils.py", line 272, in decorated_view
    return func(*args, **kwargs)
  File "/Users/connorreitz/Documents/Programming/flask_webapp/app/routes.py", line 87, in user
    page = requests.args.get('page', 1, type=int)
NameError: name 'requests' is not defined
2020-06-30 08:48:59,847 INFO: Reitz Recipes startup [in /Users/connorreitz/Documents/Programming/flask_webapp/app/__init__.py:48]
