2020-07-03 13:11:14,635 ERROR: Exception on /auth/login [GET] [in /Users/connorreitz/Documents/Programming/flask_webapp/venv/lib/python3.8/site-packages/flask/app.py:1890]
Traceback (most recent call last):
  File "/Users/connorreitz/Documents/Programming/flask_webapp/venv/lib/python3.8/site-packages/flask/app.py", line 2446, in wsgi_app
    response = self.full_dispatch_request()
  File "/Users/connorreitz/Documents/Programming/flask_webapp/venv/lib/python3.8/site-packages/flask/app.py", line 1951, in full_dispatch_request
    rv = self.handle_user_exception(e)
  File "/Users/connorreitz/Documents/Programming/flask_webapp/venv/lib/python3.8/site-packages/flask/app.py", line 1820, in handle_user_exception
    reraise(exc_type, exc_value, tb)
  File "/Users/connorreitz/Documents/Programming/flask_webapp/venv/lib/python3.8/site-packages/flask/_compat.py", line 39, in reraise
    raise value
  File "/Users/connorreitz/Documents/Programming/flask_webapp/venv/lib/python3.8/site-packages/flask/app.py", line 1949, in full_dispatch_request
    rv = self.dispatch_request()
  File "/Users/connorreitz/Documents/Programming/flask_webapp/venv/lib/python3.8/site-packages/flask/app.py", line 1935, in dispatch_request
    return self.view_functions[rule.endpoint](**req.view_args)
  File "/Users/connorreitz/Documents/Programming/flask_webapp/app/auth/routes.py", line 23, in login
    return render_template('auth/login.html', title='Sign in', form=form)
  File "/Users/connorreitz/Documents/Programming/flask_webapp/venv/lib/python3.8/site-packages/flask/templating.py", line 137, in render_template
    return _render(
  File "/Users/connorreitz/Documents/Programming/flask_webapp/venv/lib/python3.8/site-packages/flask/templating.py", line 120, in _render
    rv = template.render(context)
  File "/Users/connorreitz/Documents/Programming/flask_webapp/venv/lib/python3.8/site-packages/jinja2/environment.py", line 1090, in render
    self.environment.handle_exception()
  File "/Users/connorreitz/Documents/Programming/flask_webapp/venv/lib/python3.8/site-packages/jinja2/environment.py", line 832, in handle_exception
    reraise(*rewrite_traceback_stack(source=source))
  File "/Users/connorreitz/Documents/Programming/flask_webapp/venv/lib/python3.8/site-packages/jinja2/_compat.py", line 28, in reraise
    raise value.with_traceback(tb)
  File "/Users/connorreitz/Documents/Programming/flask_webapp/app/templates/auth/login.html", line 2, in top-level template code
    {% import 'bootstrap/wtf.html' as wtf %}
  File "/Users/connorreitz/Documents/Programming/flask_webapp/app/templates/base.html", line 1, in top-level template code
    {% extends 'bootstrap/base.html' %}
  File "/Users/connorreitz/Documents/Programming/flask_webapp/venv/lib/python3.8/site-packages/flask_bootstrap/templates/bootstrap/base.html", line 1, in top-level template code
    {% block doc -%}
  File "/Users/connorreitz/Documents/Programming/flask_webapp/venv/lib/python3.8/site-packages/flask_bootstrap/templates/bootstrap/base.html", line 3, in block "doc"
    <html{% block html_attribs %}{% endblock html_attribs %}>
  File "/Users/connorreitz/Documents/Programming/flask_webapp/venv/lib/python3.8/site-packages/flask_bootstrap/templates/bootstrap/base.html", line 11, in block "html"
    {%- endblock metas %}
  File "/Users/connorreitz/Documents/Programming/flask_webapp/venv/lib/python3.8/site-packages/flask_bootstrap/templates/bootstrap/base.html", line 12, in block "body"
  File "/Users/connorreitz/Documents/Programming/flask_webapp/app/templates/base.html", line 17, in block "navbar"
    <a class="navbar-brand" href="{{ url_for('index') }}">Reitz Recipes</a>
  File "/Users/connorreitz/Documents/Programming/flask_webapp/venv/lib/python3.8/site-packages/flask/helpers.py", line 370, in url_for
    return appctx.app.handle_url_build_error(error, endpoint, values)
  File "/Users/connorreitz/Documents/Programming/flask_webapp/venv/lib/python3.8/site-packages/flask/app.py", line 2215, in handle_url_build_error
    reraise(exc_type, exc_value, tb)
  File "/Users/connorreitz/Documents/Programming/flask_webapp/venv/lib/python3.8/site-packages/flask/_compat.py", line 39, in reraise
    raise value
  File "/Users/connorreitz/Documents/Programming/flask_webapp/venv/lib/python3.8/site-packages/flask/helpers.py", line 357, in url_for
    rv = url_adapter.build(
  File "/Users/connorreitz/Documents/Programming/flask_webapp/venv/lib/python3.8/site-packages/werkzeug/routing.py", line 2179, in build
    raise BuildError(endpoint, values, method, self)
werkzeug.routing.BuildError: Could not build url for endpoint 'index'. Did you mean 'main.index' instead?
2020-07-03 13:15:27,152 INFO: Reitz Recipes startup [in /Users/connorreitz/Documents/Programming/flask_webapp/app/__init__.py:70]
2020-07-03 13:15:38,815 ERROR: Exception on /auth/login [POST] [in /Users/connorreitz/Documents/Programming/flask_webapp/venv/lib/python3.8/site-packages/flask/app.py:1890]
Traceback (most recent call last):
  File "/Users/connorreitz/Documents/Programming/flask_webapp/venv/lib/python3.8/site-packages/flask/app.py", line 2446, in wsgi_app
    response = self.full_dispatch_request()
  File "/Users/connorreitz/Documents/Programming/flask_webapp/venv/lib/python3.8/site-packages/flask/app.py", line 1951, in full_dispatch_request
    rv = self.handle_user_exception(e)
  File "/Users/connorreitz/Documents/Programming/flask_webapp/venv/lib/python3.8/site-packages/flask/app.py", line 1820, in handle_user_exception
    reraise(exc_type, exc_value, tb)
  File "/Users/connorreitz/Documents/Programming/flask_webapp/venv/lib/python3.8/site-packages/flask/_compat.py", line 39, in reraise
    raise value
  File "/Users/connorreitz/Documents/Programming/flask_webapp/venv/lib/python3.8/site-packages/flask/app.py", line 1949, in full_dispatch_request
    rv = self.dispatch_request()
  File "/Users/connorreitz/Documents/Programming/flask_webapp/venv/lib/python3.8/site-packages/flask/app.py", line 1935, in dispatch_request
    return self.view_functions[rule.endpoint](**req.view_args)
  File "/Users/connorreitz/Documents/Programming/flask_webapp/app/auth/routes.py", line 22, in login
    return redirect(url_for('index'))
  File "/Users/connorreitz/Documents/Programming/flask_webapp/venv/lib/python3.8/site-packages/flask/helpers.py", line 370, in url_for
    return appctx.app.handle_url_build_error(error, endpoint, values)
  File "/Users/connorreitz/Documents/Programming/flask_webapp/venv/lib/python3.8/site-packages/flask/app.py", line 2215, in handle_url_build_error
    reraise(exc_type, exc_value, tb)
  File "/Users/connorreitz/Documents/Programming/flask_webapp/venv/lib/python3.8/site-packages/flask/_compat.py", line 39, in reraise
    raise value
  File "/Users/connorreitz/Documents/Programming/flask_webapp/venv/lib/python3.8/site-packages/flask/helpers.py", line 357, in url_for
    rv = url_adapter.build(
  File "/Users/connorreitz/Documents/Programming/flask_webapp/venv/lib/python3.8/site-packages/werkzeug/routing.py", line 2179, in build
    raise BuildError(endpoint, values, method, self)
werkzeug.routing.BuildError: Could not build url for endpoint 'index'. Did you mean 'main.index' instead?
2020-07-03 13:17:29,651 INFO: Reitz Recipes startup [in /Users/connorreitz/Documents/Programming/flask_webapp/app/__init__.py:70]
2020-07-03 13:17:32,711 ERROR: Exception on / [GET] [in /Users/connorreitz/Documents/Programming/flask_webapp/venv/lib/python3.8/site-packages/flask/app.py:1890]
Traceback (most recent call last):
  File "/Users/connorreitz/Documents/Programming/flask_webapp/venv/lib/python3.8/site-packages/flask/app.py", line 2446, in wsgi_app
    response = self.full_dispatch_request()
  File "/Users/connorreitz/Documents/Programming/flask_webapp/venv/lib/python3.8/site-packages/flask/app.py", line 1951, in full_dispatch_request
    rv = self.handle_user_exception(e)
  File "/Users/connorreitz/Documents/Programming/flask_webapp/venv/lib/python3.8/site-packages/flask/app.py", line 1820, in handle_user_exception
    reraise(exc_type, exc_value, tb)
  File "/Users/connorreitz/Documents/Programming/flask_webapp/venv/lib/python3.8/site-packages/flask/_compat.py", line 39, in reraise
    raise value
  File "/Users/connorreitz/Documents/Programming/flask_webapp/venv/lib/python3.8/site-packages/flask/app.py", line 1949, in full_dispatch_request
    rv = self.dispatch_request()
  File "/Users/connorreitz/Documents/Programming/flask_webapp/venv/lib/python3.8/site-packages/flask/app.py", line 1935, in dispatch_request
    return self.view_functions[rule.endpoint](**req.view_args)
  File "/Users/connorreitz/Documents/Programming/flask_webapp/venv/lib/python3.8/site-packages/flask_login/utils.py", line 272, in decorated_view
    return func(*args, **kwargs)
  File "/Users/connorreitz/Documents/Programming/flask_webapp/app/main/routes.py", line 27, in index
    page, app.config['POSTS_PER_PAGE'], False)
NameError: name 'app' is not defined
