2020-07-14 14:15:45,324 ERROR: Exception on /api/users/1 [GET] [in /Users/connorreitz/Documents/Programming/flask_webapp/venv/lib/python3.8/site-packages/flask/app.py:1890]
Traceback (most recent call last):
  File "/Users/connorreitz/Documents/Programming/flask_webapp/venv/lib/python3.8/site-packages/flask/app.py", line 2446, in wsgi_app
    response = self.full_dispatch_request()
  File "/Users/connorreitz/Documents/Programming/flask_webapp/venv/lib/python3.8/site-packages/flask/app.py", line 1951, in full_dispatch_request
    rv = self.handle_user_exception(e)
  File "/Users/connorreitz/Documents/Programming/flask_webapp/venv/lib/python3.8/site-packages/flask/app.py", line 1820, in handle_user_exception
    reraise(exc_type, exc_value, tb)
  File "/Users/connorreitz/Documents/Programming/flask_webapp/venv/lib/python3.8/site-packages/flask/_compat.py", line 39, in reraise
    raise value
  File "/Users/connorreitz/Documents/Programming/flask_webapp/venv/lib/python3.8/site-packages/flask/app.py", line 1949, in full_dispatch_request
    rv = self.dispatch_request()
  File "/Users/connorreitz/Documents/Programming/flask_webapp/venv/lib/python3.8/site-packages/flask/app.py", line 1935, in dispatch_request
    return self.view_functions[rule.endpoint](**req.view_args)
  File "/Users/connorreitz/Documents/Programming/flask_webapp/app/api/users.py", line 6, in get_user
    return jsonify(User.query.get_or_404(id).to_dict())
NameError: name 'User' is not defined
2020-07-14 14:16:07,268 INFO: Reitz Recipes startup [in /Users/connorreitz/Documents/Programming/flask_webapp/app/__init__.py:77]
2020-07-14 14:16:09,265 ERROR: Exception on /api/users/1 [GET] [in /Users/connorreitz/Documents/Programming/flask_webapp/venv/lib/python3.8/site-packages/flask/app.py:1890]
Traceback (most recent call last):
  File "/Users/connorreitz/Documents/Programming/flask_webapp/venv/lib/python3.8/site-packages/flask/app.py", line 2446, in wsgi_app
    response = self.full_dispatch_request()
  File "/Users/connorreitz/Documents/Programming/flask_webapp/venv/lib/python3.8/site-packages/flask/app.py", line 1951, in full_dispatch_request
    rv = self.handle_user_exception(e)
  File "/Users/connorreitz/Documents/Programming/flask_webapp/venv/lib/python3.8/site-packages/flask/app.py", line 1820, in handle_user_exception
    reraise(exc_type, exc_value, tb)
  File "/Users/connorreitz/Documents/Programming/flask_webapp/venv/lib/python3.8/site-packages/flask/_compat.py", line 39, in reraise
    raise value
  File "/Users/connorreitz/Documents/Programming/flask_webapp/venv/lib/python3.8/site-packages/flask/app.py", line 1949, in full_dispatch_request
    rv = self.dispatch_request()
  File "/Users/connorreitz/Documents/Programming/flask_webapp/venv/lib/python3.8/site-packages/flask/app.py", line 1935, in dispatch_request
    return self.view_functions[rule.endpoint](**req.view_args)
  File "/Users/connorreitz/Documents/Programming/flask_webapp/app/api/users.py", line 7, in get_user
    return jsonify(User.query.get_or_404(id).to_dict())
  File "/Users/connorreitz/Documents/Programming/flask_webapp/app/models.py", line 114, in to_dict
    'self': url_for('api.get_user', id=self.id),
NameError: name 'url_for' is not defined
2020-07-14 14:17:06,129 ERROR: Exception on /api/users/1 [GET] [in /Users/connorreitz/Documents/Programming/flask_webapp/venv/lib/python3.8/site-packages/flask/app.py:1890]
Traceback (most recent call last):
  File "/Users/connorreitz/Documents/Programming/flask_webapp/venv/lib/python3.8/site-packages/flask/app.py", line 2446, in wsgi_app
    response = self.full_dispatch_request()
  File "/Users/connorreitz/Documents/Programming/flask_webapp/venv/lib/python3.8/site-packages/flask/app.py", line 1951, in full_dispatch_request
    rv = self.handle_user_exception(e)
  File "/Users/connorreitz/Documents/Programming/flask_webapp/venv/lib/python3.8/site-packages/flask/app.py", line 1820, in handle_user_exception
    reraise(exc_type, exc_value, tb)
  File "/Users/connorreitz/Documents/Programming/flask_webapp/venv/lib/python3.8/site-packages/flask/_compat.py", line 39, in reraise
    raise value
  File "/Users/connorreitz/Documents/Programming/flask_webapp/venv/lib/python3.8/site-packages/flask/app.py", line 1949, in full_dispatch_request
    rv = self.dispatch_request()
  File "/Users/connorreitz/Documents/Programming/flask_webapp/venv/lib/python3.8/site-packages/flask/app.py", line 1935, in dispatch_request
    return self.view_functions[rule.endpoint](**req.view_args)
  File "/Users/connorreitz/Documents/Programming/flask_webapp/app/api/users.py", line 7, in get_user
    return jsonify(User.query.get_or_404(id).to_dict())
  File "/Users/connorreitz/Documents/Programming/flask_webapp/app/models.py", line 114, in to_dict
    'self': url_for('api.get_user', id=self.id),
NameError: name 'url_for' is not defined
2020-07-14 14:18:33,811 INFO: Reitz Recipes startup [in /Users/connorreitz/Documents/Programming/flask_webapp/app/__init__.py:77]
2020-07-14 14:22:13,601 INFO: Reitz Recipes startup [in /Users/connorreitz/Documents/Programming/flask_webapp/app/__init__.py:77]
2020-07-14 14:26:55,535 INFO: Reitz Recipes startup [in /Users/connorreitz/Documents/Programming/flask_webapp/app/__init__.py:77]
2020-07-14 14:27:00,704 ERROR: Exception on /api/users [GET] [in /Users/connorreitz/Documents/Programming/flask_webapp/venv/lib/python3.8/site-packages/flask/app.py:1890]
Traceback (most recent call last):
  File "/Users/connorreitz/Documents/Programming/flask_webapp/venv/lib/python3.8/site-packages/flask/app.py", line 2446, in wsgi_app
    response = self.full_dispatch_request()
  File "/Users/connorreitz/Documents/Programming/flask_webapp/venv/lib/python3.8/site-packages/flask/app.py", line 1951, in full_dispatch_request
    rv = self.handle_user_exception(e)
  File "/Users/connorreitz/Documents/Programming/flask_webapp/venv/lib/python3.8/site-packages/flask/app.py", line 1820, in handle_user_exception
    reraise(exc_type, exc_value, tb)
  File "/Users/connorreitz/Documents/Programming/flask_webapp/venv/lib/python3.8/site-packages/flask/_compat.py", line 39, in reraise
    raise value
  File "/Users/connorreitz/Documents/Programming/flask_webapp/venv/lib/python3.8/site-packages/flask/app.py", line 1949, in full_dispatch_request
    rv = self.dispatch_request()
  File "/Users/connorreitz/Documents/Programming/flask_webapp/venv/lib/python3.8/site-packages/flask/app.py", line 1935, in dispatch_request
    return self.view_functions[rule.endpoint](**req.view_args)
  File "/Users/connorreitz/Documents/Programming/flask_webapp/app/api/users.py", line 11, in get_users
    page = requests.args.get('page', 1, type=int)
NameError: name 'requests' is not defined
2020-07-14 14:27:24,986 INFO: Reitz Recipes startup [in /Users/connorreitz/Documents/Programming/flask_webapp/app/__init__.py:77]
2020-07-14 14:27:26,510 ERROR: Exception on /api/users [GET] [in /Users/connorreitz/Documents/Programming/flask_webapp/venv/lib/python3.8/site-packages/flask/app.py:1890]
Traceback (most recent call last):
  File "/Users/connorreitz/Documents/Programming/flask_webapp/venv/lib/python3.8/site-packages/flask/app.py", line 2446, in wsgi_app
    response = self.full_dispatch_request()
  File "/Users/connorreitz/Documents/Programming/flask_webapp/venv/lib/python3.8/site-packages/flask/app.py", line 1951, in full_dispatch_request
    rv = self.handle_user_exception(e)
  File "/Users/connorreitz/Documents/Programming/flask_webapp/venv/lib/python3.8/site-packages/flask/app.py", line 1820, in handle_user_exception
    reraise(exc_type, exc_value, tb)
  File "/Users/connorreitz/Documents/Programming/flask_webapp/venv/lib/python3.8/site-packages/flask/_compat.py", line 39, in reraise
    raise value
  File "/Users/connorreitz/Documents/Programming/flask_webapp/venv/lib/python3.8/site-packages/flask/app.py", line 1949, in full_dispatch_request
    rv = self.dispatch_request()
  File "/Users/connorreitz/Documents/Programming/flask_webapp/venv/lib/python3.8/site-packages/flask/app.py", line 1935, in dispatch_request
    return self.view_functions[rule.endpoint](**req.view_args)
  File "/Users/connorreitz/Documents/Programming/flask_webapp/app/api/users.py", line 13, in get_users
    data = User.to_collection_dict(Usery.query, page, per_page, 'api.get_users')
NameError: name 'Usery' is not defined
2020-07-14 14:27:39,792 INFO: Reitz Recipes startup [in /Users/connorreitz/Documents/Programming/flask_webapp/app/__init__.py:77]
